<?xml version="1.0" ?>
<!-- =================================================================================== -->
<!-- |    This document was autogenerated by xacro from basic_robot.urdf.xacro         | -->
<!-- |    EDITING THIS FILE BY HAND IS NOT RECOMMENDED                                 | -->
<!-- =================================================================================== -->
<robot name="basic_robot">
  <gazebo>
    <plugin filename="gz-sim-diff-drive-system" name="gz::sim::systems::DiffDrive">
      <left_joint>left_wheel_joint</left_joint>
      <right_joint>right_wheel_joint</right_joint>
      <topic>/cmd_vel</topic>
      <odom_topic>/odom</odom_topic>
      <tf_topic>/basic_robot/tf</tf_topic>
      <wheel_separation>0.825</wheel_separation>
      <wheel_radius>0.4</wheel_radius>
      <odom_publish_frequency>50</odom_publish_frequency>
      <frame_id>odom</frame_id>
      <child_frame_id>chassis</child_frame_id>
      <max_linear_velocity>2.0</max_linear_velocity>
      <max_angular_velocity>6.28</max_angular_velocity>
    </plugin>
    <plugin filename="gz-sim-joint-state-publisher-system" name="gz::sim::systems::JointStatePublisher">
      <topic>/joint_states</topic>
    </plugin>
    <plugin filename="gz-sim-pose-publisher-system" name="gz::sim::systems::PosePublisher">
      <publish_model_pose>true</publish_model_pose>
      <publish_link_pose>true</publish_link_pose>
      <publish_nested_model_pose>true</publish_nested_model_pose>
      <use_pose_vector_msg>true</use_pose_vector_msg>
      <update_frequency>30</update_frequency>
      <static_publisher>true</static_publisher>
      <static_update_frequency>30</static_update_frequency>
    </plugin>
  </gazebo>
  <material name="electric-blue">
    <color rgba="0.0 0.5 1.0 1.0"/>
  </material>
  <material name="crimson-red">
    <color rgba="0.8 0.0 0.2 1.0"/>
  </material>
  <material name="lime-green">
    <color rgba="0.2 1.0 0.2 1.0"/>
  </material>
  <material name="gunmetal-gray">
    <color rgba="0.2 0.2 0.25 1.0"/>
  </material>
  <!-- Body Link -->
  <link name="chassis">
    <visual>
      <origin rpy="0.0 0.0 0.0" xyz="0.0 0.0 0.0"/>
      <geometry>
        <box size="0.825 0.825 0.075"/>
      </geometry>
      <material name="gunmetal-gray"/>
    </visual>
    <inertial>
      <origin rpy="0 0 0" xyz="0 0 -0.25"/>
      <mass value="15.0"/>
      <inertia ixx="0.8578125" ixy="0.0" ixz="0.0" iyy="0.8578125" iyz="0.0" izz="1.7015625"/>
    </inertial>
    <collision>
      <geometry>
        <box size="0.825 0.825 0.075"/>
      </geometry>
      <surface>
        <friction>
          <ode>
            <mu>0.8</mu>
            <mu2>0.8</mu2>
          </ode>
        </friction>
      </surface>
    </collision>
  </link>
  <link name="left_wheel">
    <visual>
      <origin rpy="1.570795 0.0 0.0" xyz="0.0 0.0 0.0"/>
      <geometry>
        <cylinder length="0.05" radius="0.4"/>
      </geometry>
      <material name="electric-blue"/>
    </visual>
    <inertial>
      <origin rpy="0 0 0" xyz="0 0 0"/>
      <mass value="2.0"/>
      <inertia ixx="0.0804167" ixy="0.0" ixz="0.0" iyy="0.0804167" iyz="0.0" izz="0.16"/>
    </inertial>
    <collision>
      <origin rpy="1.570795 0.0 0.0" xyz="0.0 0.0 0.0"/>
      <geometry>
        <cylinder length="0.05" radius="0.4"/>
      </geometry>
      <surface>
        <friction>
          <ode>
            <mu>1.2</mu>
            <mu2>1.2</mu2>
          </ode>
        </friction>
      </surface>
    </collision>
  </link>
  <link name="right_wheel">
    <visual>
      <origin rpy="1.570795 0.0 0.0" xyz="0.0 0.0 0.0"/>
      <geometry>
        <cylinder length="0.05" radius="0.4"/>
      </geometry>
      <material name="crimson-red"/>
    </visual>
    <inertial>
      <origin rpy="0 0 0" xyz="0 0 0"/>
      <mass value="2.0"/>
      <inertia ixx="0.0804167" ixy="0.0" ixz="0.0" iyy="0.0804167" iyz="0.0" izz="0.16"/>
    </inertial>
    <collision>
      <origin rpy="1.570795 0.0 0.0" xyz="0.0 0.0 0.0"/>
      <geometry>
        <cylinder length="0.05" radius="0.4"/>
      </geometry>
      <surface>
        <friction>
          <ode>
            <mu>1.2</mu>
            <mu2>1.2</mu2>
          </ode>
        </friction>
      </surface>
    </collision>
  </link>
  <link name="lidar_dome">
    <visual>
      <origin rpy="0.0 0.0 0.0" xyz="0.0 0.0 0.0"/>
      <geometry>
        <sphere radius="0.03125"/>
      </geometry>
      <material name="lime-green"/>
    </visual>
    <inertial>
      <origin rpy="0 0 0" xyz="0 0 0"/>
      <mass value="0.002"/>
      <inertia ixx="7.8125e-07" ixy="0.0" ixz="0.0" iyy="7.8125e-07" iyz="0.0" izz="7.8125e-07"/>
    </inertial>
    <collision>
      <geometry>
        <sphere radius="0.03125"/>
      </geometry>
    </collision>
  </link>
  <joint name="left_wheel_joint" type="continuous">
    <origin rpy="0 0 0" xyz="0 0.4375 0"/>
    <parent link="chassis"/>
    <child link="left_wheel"/>
    <axis xyz="0 1 0"/>
    <limit effort="100" velocity="5.0"/>
    <dynamics damping="0.5" friction="0.2"/>
  </joint>
  <joint name="right_wheel_joint" type="continuous">
    <origin rpy="0 0 0" xyz="0 -0.4375 0"/>
    <parent link="chassis"/>
    <child link="right_wheel"/>
    <axis xyz="0 1 0"/>
    <limit effort="100" velocity="5.0"/>
    <dynamics damping="0.5" friction="0.2"/>
  </joint>
  <joint name="lidar_joint" type="fixed">
    <origin rpy="0 0 0" xyz="0.3 0 0.025"/>
    <parent link="chassis"/>
    <child link="lidar_dome"/>
  </joint>
</robot>
